Workbook

Sheet 出口中国香港特别行政区
B1: 出口：中国香港特别行政区
A2: 区域 | B2: 新加坡
A3: 次国家
A4: 频率 | B4: 月
A5: 单位 | B5: 百万新加坡元
A6: 数据来源 | B6: Enterprise Singapore
A7: 状态 | B7: 继续
A8: 数列ID | B8: 36422401 (SJFG)
A9: SR码 | B9: SR520885
A10: 贸易代码
A11: 助记符
A12: 函数说明
A13: 首次观测日期 | B13: 01/1976
A14: 最后观测日期 | B14: 01/2026
A15: 最后更新时间 | B15: 16/02/2026
A16: 数列备注 | B16: [COVID-19-IMPACT]
A17: 建议
A18: 平均 MEAN | B18: 2579.842618968387
A19: 方差 | B19: 5135504.378208526
A20: 标准差 | B20: 2266.1651259801274
A21: 偏度 | B21: 0.5123974392139459
A22: 峰度 | B22: -1.1468006
A23: 变异系数 | B23: 0.8784121594542496
A24: 最小 | B24: 74.648
A25: 最大 | B25: 8154
A26: 中位数 | B26: 1600.338
A27: 总和 SUM | B27: 1550485.4140000008
A28: 减 SUBTRACT | B28: -8079.352
A29: 参照期间 | B29: 601
A30: 01/1976 | B30: 108.223
A31: 02/1976 | B31: 95.182
A32: 03/1976 | B32: 77.688
A33: 04/1976 | B33: 133.127
A34: 05/1976 | B34: 74.648
A35: 06/1976 | B35: 110.924
A36: 07/1976 | B36: 135.554
A37: 08/1976 | B37: 81.298
A38: 09/1976 | B38: 103.234
A39: 10/1976 | B39: 112.85
... A630: 01/2026 | B630: 8154

Sheet 出口中国台湾
B1: 出口：中国台湾
A2: 区域 | B2: 新加坡
A3: 次国家
A4: 频率 | B4: 月
A5: 单位 | B5: 百万新加坡元
A6: 数据来源 | B6: Enterprise Singapore
A7: 状态 | B7: 继续
A8: 数列ID | B8: 36423001 (SJFN)
A9: SR码 | B9: SR520894
A10: 贸易代码
A11: 助记符
A12: 函数说明
A13: 首次观测日期 | B13: 01/1976
A14: 最后观测日期 | B14: 01/2026
A15: 最后更新时间 | B15: 16/02/2026
A16: 数列备注
A17: 建议
A18: 平均 MEAN | B18: 1057.4860016638943
A19: 方差 | B19: 1258209.048641876
A20: 标准差 | B20: 1121.6991792106635
A21: 偏度 | B21: 3.004410821403535
A22: 峰度 | B22: 17.913312134843324
A23: 变异系数 | B23: 1.060722484690798
A24: 最小 | B24: 8.373
A25: 最大 | B25: 11214.6
A26: 中位数 | B26: 891.374
A27: 总和 SUM | B27: 635549.0869999998
A28: 减 SUBTRACT | B28: -11206.227
A29: 参照期间 | B29: 601
A30: 01/1976 | B30: 12.283
A31: 02/1976 | B31: 8.373
A32: 03/1976 | B32: 12.968
A33: 04/1976 | B33: 10.569
A34: 05/1976 | B34: 11.585
A35: 06/1976 | B35: 12.086
A36: 07/1976 | B36: 13.551
A37: 08/1976 | B37: 18.776
A38: 09/1976 | B38: 16.346
A39: 10/1976 | B39: 13.564
... A630: 01/2026 | B630: 11214.6

Sheet Sheet9
A1: 日期 | B1: 月 | C1: 年 | D1: 墨西哥 | E1: 马来西亚 | F1: 韩国 | G1: 越南 | H1: 美国 | I1: 泰国 | J1: 日本 | K1: 印度 | L1: 中国 | M1: 台湾 | N1: 香港
A2: 01/1976 | B2: 1 | C2: 1976 | D2: =VLOOKUP(A2,出口墨西哥!$A$30:$B$630,2,0) -> 4.421 | E2: =VLOOKUP(A2,出口马来西亚!$A$30:$B$630,2,0) -> 180.289 | F2: =VLOOKUP($A2,出口韩国!$A$30:$B$630,2,0) -> 10.344 | G2: =VLOOKUP($A2,出口越南!$A$30:$B$426,2,0) -> #N/A | H2: =VLOOKUP($A2,出口美国!$A$30:$B$630,2,0) -> 244.148 | I2: =VLOOKUP($A2,出口泰国!$A$30:$B$630,2,0) -> 44.796 | J2: =VLOOKUP($A2,出口日本!$A$30:$B$630,2,0) -> 130.744 | K2: =VLOOKUP($A2,出口印度!$A$30:$B$630,2,0) -> 9.368 | L2: =VLOOKUP($A2,出口中国!$A$30:$B$630,2,0) -> 11.604 | M2: =VLOOKUP($A2,出口中国台湾!$A$30:$B$630,2,0) -> 12.283 | N2: =VLOOKUP($A2,出口中国香港特别行政区!$A$30:$B$630,2,0) -> 108.223
A3: 02/1976 | B3: 2 | C3: 1976 | D3: =VLOOKUP(A3,出口墨西哥!$A$30:$B$630,2,0) -> 2.171 | E3: =VLOOKUP(A3,出口马来西亚!$A$30:$B$630,2,0) -> 171.755 | F3: =VLOOKUP($A3,出口韩国!$A$30:$B$630,2,0) -> 10.413 | G3: =VLOOKUP($A3,出口越南!$A$30:$B$426,2,0) -> #N/A | H3: =VLOOKUP($A3,出口美国!$A$30:$B$630,2,0) -> 151.791 | I3: =VLOOKUP($A3,出口泰国!$A$30:$B$630,2,0) -> 31.867 | J3: =VLOOKUP($A3,出口日本!$A$30:$B$630,2,0) -> 107.053 | K3: =VLOOKUP($A3,出口印度!$A$30:$B$630,2,0) -> 9.328 | L3: =VLOOKUP($A3,出口中国!$A$30:$B$630,2,0) -> 8.486 | M3: =VLOOKUP($A3,出口中国台湾!$A$30:$B$630,2,0) -> 8.373 | N3: =VLOOKUP($A3,出口中国香港特别行政区!$A$30:$B$630,2,0) -> 95.182 | R3: Row Labels | S3: Sum of 香港 | T3: Sum of 台湾 | U3: Sum of 中国 | V3: Sum of 印度 | W3: Sum of 日本 | X3: Sum of 泰国 | Y3: Sum of 美国 | Z3: Sum of 韩国 | AA3: Sum of 马来西亚 | AB3: Sum of 墨西哥 | AC3: Sum of 越南
A4: 03/1976 | B4: 3 | C4: 1976 | D4: =VLOOKUP(A4,出口墨西哥!$A$30:$B$630,2,0) -> 4.053 | E4: =VLOOKUP(A4,出口马来西亚!$A$30:$B$630,2,0) -> 201.753 | F4: =VLOOKUP($A4,出口韩国!$A$30:$B$630,2,0) -> 14.527 | G4: =VLOOKUP($A4,出口越南!$A$30:$B$426,2,0) -> #N/A | H4: =VLOOKUP($A4,出口美国!$A$30:$B$630,2,0) -> 193.48 | I4: =VLOOKUP($A4,出口泰国!$A$30:$B$630,2,0) -> 48.372 | J4: =VLOOKUP($A4,出口日本!$A$30:$B$630,2,0) -> 130.205 | K4: =VLOOKUP($A4,出口印度!$A$30:$B$630,2,0) -> 10.472 | L4: =VLOOKUP($A4,出口中国!$A$30:$B$630,2,0) -> 1.318 | M4: =VLOOKUP($A4,出口中国台湾!$A$30:$B$630,2,0) -> 12.968 | N4: =VLOOKUP($A4,出口中国香港特别行政区!$A$30:$B$630,2,0) -> 77.688 | R4: 1976 | S4: 1266.599 | T4: 166.702 | U4: 95.422 | V4: 113.135 | W4: 1668.803 | X4: 485.988 | Y4: 2393.467 | Z4: 182.648 | AA4: 2480.913 | AB4: 41.269 | AC4: #N/A
A5: 04/1976 | B5: 4 | C5: 1976 | D5: =VLOOKUP(A5,出口墨西哥!$A$30:$B$630,2,0) -> 3.836 | E5: =VLOOKUP(A5,出口马来西亚!$A$30:$B$630,2,0) -> 207.398 | F5: =VLOOKUP($A5,出口韩国!$A$30:$B$630,2,0) -> 11.577 | G5: =VLOOKUP($A5,出口越南!$A$30:$B$426,2,0) -> #N/A | H5: =VLOOKUP($A5,出口美国!$A$30:$B$630,2,0) -> 161.726 | I5: =VLOOKUP($A5,出口泰国!$A$30:$B$630,2,0) -> 52.854 | J5: =VLOOKUP($A5,出口日本!$A$30:$B$630,2,0) -> 135.849 | K5: =VLOOKUP($A5,出口印度!$A$30:$B$630,2,0) -> 6.431 | L5: =VLOOKUP($A5,出口中国!$A$30:$B$630,2,0) -> 2.867 | M5: =VLOOKUP($A5,出口中国台湾!$A$30:$B$630,2,0) -> 10.569 | N5: =VLOOKUP($A5,出口中国香港特别行政区!$A$30:$B$630,2,0) -> 133.127 | R5: 1977 | S5: 1474.027 | T5: 292.349 | U5: 144.672 | V5: 346.221 | W5: 1918.118 | X5: 562.122 | Y5: 3120.845 | Z5: 313.574 | AA5: 2873.944 | AB5: 57.718 | AC5: #N/A
A6: 05/1976 | B6: 5 | C6: 1976 | D6: =VLOOKUP(A6,出口墨西哥!$A$30:$B$630,2,0) -> 4.832 | E6: =VLOOKUP(A6,出口马来西亚!$A$30:$B$630,2,0) -> 188.857 | F6: =VLOOKUP($A6,出口韩国!$A$30:$B$630,2,0) -> 13.667 | G6: =VLOOKUP($A6,出口越南!$A$30:$B$426,2,0) -> #N/A | H6: =VLOOKUP($A6,出口美国!$A$30:$B$630,2,0) -> 191.72 | I6: =VLOOKUP($A6,出口泰国!$A$30:$B$630,2,0) -> 49.975 | J6: =VLOOKUP($A6,出口日本!$A$30:$B$630,2,0) -> 142.944 | K6: =VLOOKUP($A6,出口印度!$A$30:$B$630,2,0) -> 8.892 | L6: =VLOOKUP($A6,出口中国!$A$30:$B$630,2,0) -> 2.018 | M6: =VLOOKUP($A6,出口中国台湾!$A$30:$B$630,2,0) -> 11.585 | N6: =VLOOKUP($A6,出口中国香港特别行政区!$A$30:$B$630,2,0) -> 74.648 | R6: 1978 | S6: 1630.391 | T6: 349.182 | U6: 130.65 | V6: 621.608 | W6: 2226.003 | X6: 894.136 | Y6: 3684.535 | Z6: 400.064 | AA6: 3193.504 | AB6: 59.169 | AC6: #N/A
A7: 06/1976 | B7: 6 | C7: 1976 | D7: =VLOOKUP(A7,出口墨西哥!$A$30:$B$630,2,0) -> 2.452 | E7: =VLOOKUP(A7,出口马来西亚!$A$30:$B$630,2,0) -> 196.107 | F7: =VLOOKUP($A7,出口韩国!$A$30:$B$630,2,0) -> 15.814 | G7: =VLOOKUP($A7,出口越南!$A$30:$B$426,2,0) -> #N/A | H7: =VLOOKUP($A7,出口美国!$A$30:$B$630,2,0) -> 195.342 | I7: =VLOOKUP($A7,出口泰国!$A$30:$B$630,2,0) -> 34.262 | J7: =VLOOKUP($A7,出口日本!$A$30:$B$630,2,0) -> 104.178 | K7: =VLOOKUP($A7,出口印度!$A$30:$B$630,2,0) -> 8.74 | L7: =VLOOKUP($A7,出口中国!$A$30:$B$630,2,0) -> 7.193 | M7: =VLOOKUP($A7,出口中国台湾!$A$30:$B$630,2,0) -> 12.086 | N7: =VLOOKUP($A7,出口中国香港特别行政区!$A$30:$B$630,2,0) -> 110.924 | R7: 1979 | S7: 2088.403 | T7: 450.574 | U7: 369.576 | V7: 490.167 | W7: 2967.677 | X7: 1320.487 | Y7: 4265.881 | Z7: 500.44 | AA7: 4427.43 | AB7: 74.299 | AC7: #N/A
A8: 07/1976 | B8: 7 | C8: 1976 | D8: =VLOOKUP(A8,出口墨西哥!$A$30:$B$630,2,0) -> 3.999 | E8: =VLOOKUP(A8,出口马来西亚!$A$30:$B$630,2,0) -> 231.574 | F8: =VLOOKUP($A8,出口韩国!$A$30:$B$630,2,0) -> 16.554 | G8: =VLOOKUP($A8,出口越南!$A$30:$B$426,2,0) -> #N/A | H8: =VLOOKUP($A8,出口美国!$A$30:$B$630,2,0) -> 229.319 | I8: =VLOOKUP($A8,出口泰国!$A$30:$B$630,2,0) -> 35.561 | J8: =VLOOKUP($A8,出口日本!$A$30:$B$630,2,0) -> 162.027 | K8: =VLOOKUP($A8,出口印度!$A$30:$B$630,2,0) -> 10.637 | L8: =VLOOKUP($A8,出口中国!$A$30:$B$630,2,0) -> 3.263 | M8: =VLOOKUP($A8,出口中国台湾!$A$30:$B$630,2,0) -> 13.551 | N8: =VLOOKUP($A8,出口中国香港特别行政区!$A$30:$B$630,2,0) -> 135.554 | R8: 1980 | S8: 3195.926 | T8: 701.957 | U8: 657.945 | V8: 961.701 | W8: 3338.278 | X8: 1809.32 | Y8: 5271.954 | Z8: 621.854 | AA8: 6218 | AB8: 92.573 | AC8: #N/A
A9: 08/1976 | B9: 8 | C9: 1976 | D9: =VLOOKUP(A9,出口墨西哥!$A$30:$B$630,2,0) -> 1.884 | E9: =VLOOKUP(A9,出口马来西亚!$A$30:$B$630,2,0) -> 201.877 | F9: =VLOOKUP($A9,出口韩国!$A$30:$B$630,2,0) -> 18.734 | G9: =VLOOKUP($A9,出口越南!$A$30:$B$426,2,0) -> #N/A | H9: =VLOOKUP($A9,出口美国!$A$30:$B$630,2,0) -> 175.253 | I9: =VLOOKUP($A9,出口泰国!$A$30:$B$630,2,0) -> 33.179 | J9: =VLOOKUP($A9,出口日本!$A$30:$B$630,2,0) -> 135.335 | K9: =VLOOKUP($A9,出口印度!$A$30:$B$630,2,0) -> 11.026 | L9: =VLOOKUP($A9,出口中国!$A$30:$B$630,2,0) -> 6.876 | M9: =VLOOKUP($A9,出口中国台湾!$A$30:$B$630,2,0) -> 18.776 | N9: =VLOOKUP($A9,出口中国香港特别行政区!$A$30:$B$630,2,0) -> 81.298 | R9: 1981 | S9: 3881.364 | T9: 606.597 | U9: 377.255 | V9: 1193.648 | W9: 4487.588 | X9: 1864.574 | Y9: 5848.678 | Z9: 621.47 | AA9: 6906.624 | AB9: 80.963 | AC9: #N/A
A10: 09/1976 | B10: 9 | C10: 1976 | D10: =VLOOKUP(A10,出口墨西哥!$A$30:$B$630,2,0) -> 4.9 | E10: =VLOOKUP(A10,出口马来西亚!$A$30:$B$630,2,0) -> 226.243 | F10: =VLOOKUP($A10,出口韩国!$A$30:$B$630,2,0) -> 17.039 | G10: =VLOOKUP($A10,出口越南!$A$30:$B$426,2,0) -> #N/A | H10: =VLOOKUP($A10,出口美国!$A$30:$B$630,2,0) -> 215.515 | I10: =VLOOKUP($A10,出口泰国!$A$30:$B$630,2,0) -> 41.163 | J10: =VLOOKUP($A10,出口日本!$A$30:$B$630,2,0) -> 174.935 | K10: =VLOOKUP($A10,出口印度!$A$30:$B$630,2,0) -> 10.11 | L10: =VLOOKUP($A10,出口中国!$A$30:$B$630,2,0) -> 3.677 | M10: =VLOOKUP($A10,出口中国台湾!$A$30:$B$630,2,0) -> 16.346 | N10: =VLOOKUP($A10,出口中国香港特别行政区!$A$30:$B$630,2,0) -> 103.234 | R10: 1982 | S10: 3740.999 | T10: 575.792 | U10: 516.669 | V10: 1151.56 | W10: 4843.889 | X10: 1707.995 | Y10: 5593.348 | Z10: 678.351 | AA10: 7858.865 | AB10: 38.937 | AC10: #N/A
A11: 10/1976 | B11: 10 | C11: 1976 | D11: =VLOOKUP(A11,出口墨西哥!$A$30:$B$630,2,0) -> 3.081 | E11: =VLOOKUP(A11,出口马来西亚!$A$30:$B$630,2,0) -> 216.321 | F11: =VLOOKUP($A11,出口韩国!$A$30:$B$630,2,0) -> 18.295 | G11: =VLOOKUP($A11,出口越南!$A$30:$B$426,2,0) -> #N/A | H11: =VLOOKUP($A11,出口美国!$A$30:$B$630,2,0) -> 201.301 | I11: =VLOOKUP($A11,出口泰国!$A$30:$B$630,2,0) -> 32.526 | J11: =VLOOKUP($A11,出口日本!$A$30:$B$630,2,0) -> 155.85 | K11: =VLOOKUP($A11,出口印度!$A$30:$B$630,2,0) -> 10.112 | L11: =VLOOKUP($A11,出口中国!$A$30:$B$630,2,0) -> 3.934 | M11: =VLOOKUP($A11,出口中国台湾!$A$30:$B$630,2,0) -> 13.564 | N11: =VLOOKUP($A11,出口中国香港特别行政区!$A$30:$B$630,2,0) -> 112.85 | R11: 1983 | S11: 3131.997 | T11: 687.475 | U11: 449.831 | V11: 923.371 | W11: 4244.385 | X11: 1994.686 | Y11: 8373.69 | Z11: 964.578 | AA11: 8121.316 | AB11: 26.2 | AC11: #N/A
A12: 11/1976 | B12: 11 | C12: 1976 | D12: =VLOOKUP(A12,出口墨西哥!$A$30:$B$630,2,0) -> 3.697 | E12: =VLOOKUP(A12,出口马来西亚!$A$30:$B$630,2,0) -> 254.307 | F12: =VLOOKUP($A12,出口韩国!$A$30:$B$630,2,0) -> 17.335 | G12: =VLOOKUP($A12,出口越南!$A$30:$B$426,2,0) -> #N/A | H12: =VLOOKUP($A12,出口美国!$A$30:$B$630,2,0) -> 224.226 | I12: =VLOOKUP($A12,出口泰国!$A$30:$B$630,2,0) -> 37.672 | J12: =VLOOKUP($A12,出口日本!$A$30:$B$630,2,0) -> 119.085 | K12: =VLOOKUP($A12,出口印度!$A$30:$B$630,2,0) -> 6.407 | L12: =VLOOKUP($A12,出口中国!$A$30:$B$630,2,0) -> 39.121 | M12: =VLOOKUP($A12,出口中国台湾!$A$30:$B$630,2,0) -> 20.38 | N12: =VLOOKUP($A12,出口中国香港特别行政区!$A$30:$B$630,2,0) -> 101.267 | R12: 1984 | S12: 3176.202 | T12: 829.619 | U12: 519.305 | V12: 1413.333 | W12: 4806.697 | X12: 2458.146 | Y12: 10291.732 | Z12: 814.183 | AA12: 8324.177 | AB12: 29.559 | AC12: #N/A
A13: 12/1976 | B13: 12 | C13: 1976 | D13: =VLOOKUP(A13,出口墨西哥!$A$30:$B$630,2,0) -> 1.943 | E13: =VLOOKUP(A13,出口马来西亚!$A$30:$B$630,2,0) -> 204.432 | F13: =VLOOKUP($A13,出口韩国!$A$30:$B$630,2,0) -> 18.349 | G13: =VLOOKUP($A13,出口越南!$A$30:$B$426,2,0) -> #N/A | H13: =VLOOKUP($A13,出口美国!$A$30:$B$630,2,0) -> 209.646 | I13: =VLOOKUP($A13,出口泰国!$A$30:$B$630,2,0) -> 43.761 | J13: =VLOOKUP($A13,出口日本!$A$30:$B$630,2,0) -> 170.598 | K13: =VLOOKUP($A13,出口印度!$A$30:$B$630,2,0) -> 11.612 | L13: =VLOOKUP($A13,出口中国!$A$30:$B$630,2,0) -> 5.065 | M13: =VLOOKUP($A13,出口中国台湾!$A$30:$B$630,2,0) -> 16.221 | N13: =VLOOKUP($A13,出口中国香港特别行政区!$A$30:$B$630,2,0) -> 132.604 | R13: 1985 | S13: 3197.43 | T13: 855.174 | U13: 730.159 | V13: 1069.032 | W13: 4722.18 | X13: 2092.453 | Y13: 10619.016 | Z13: 619.521 | AA13: 7786.739 | AB13: 39.049 | AC13: #N/A
A14: 01/1977 | B14: 1 | C14: 1977 | D14: =VLOOKUP(A14,出口墨西哥!$A$30:$B$630,2,0) -> 4.22 | E14: =VLOOKUP(A14,出口马来西亚!$A$30:$B$630,2,0) -> 218.018 | F14: =VLOOKUP($A14,出口韩国!$A$30:$B$630,2,0) -> 20.348 | G14: =VLOOKUP($A14,出口越南!$A$30:$B$426,2,0) -> #N/A | H14: =VLOOKUP($A14,出口美国!$A$30:$B$630,2,0) -> 288.103 | I14: =VLOOKUP($A14,出口泰国!$A$30:$B$630,2,0) -> 30.686 | J14: =VLOOKUP($A14,出口日本!$A$30:$B$630,2,0) -> 123.928 | K14: =VLOOKUP($A14,出口印度!$A$30:$B$630,2,0) -> 11.899 | L14: =VLOOKUP($A14,出口中国!$A$30:$B$630,2,0) -> 8.355 | M14: =VLOOKUP($A14,出口中国台湾!$A$30:$B$630,2,0) -> 19.446 | N14: =VLOOKUP($A14,出口中国香港特别行政区!$A$30:$B$630,2,0) -> 101.298 | R14: 1986 | S14: 3182.922 | T14: 1097.164 | U14: 1243.762 | V14: 1027.76 | W14: 4204.388 | X14: 1787.716 | Y14: 11436.344 | Z14: 703.019 | AA14: 7244.641 | AB14: 35.171 | AC14: #N/A
A15: 02/1977 | B15: 2 | C15: 1977 | D15: =VLOOKUP(A15,出口墨西哥!$A$30:$B$630,2,0) -> 3.105 | E15: =VLOOKUP(A15,出口马来西亚!$A$30:$B$630,2,0) -> 186.543 | F15: =VLOOKUP($A15,出口韩国!$A$30:$B$630,2,0) -> 12.338 | G15: =VLOOKUP($A15,出口越南!$A$30:$B$426,2,0) -> #N/A | H15: =VLOOKUP($A15,出口美国!$A$30:$B$630,2,0) -> 226.111 | I15: =VLOOKUP($A15,出口泰国!$A$30:$B$630,2,0) -> 32.297 | J15: =VLOOKUP($A15,出口日本!$A$30:$B$630,2,0) -> 122.073 | K15: =VLOOKUP($A15,出口印度!$A$30:$B$630,2,0) -> 20.365 | L15: =VLOOKUP($A15,出口中国!$A$30:$B$630,2,0) -> 3.437 | M15: =VLOOKUP($A15,出口中国台湾!$A$30:$B$630,2,0) -> 16.029 | N15: =VLOOKUP($A15,出口中国香港特别行政区!$A$30:$B$630,2,0) -> 96.952 | R15: 1987 | S15: 3814.916 | T15: 1636.704 | U15: 1546.806 | V15: 1170.161 | W15: 5449.263 | X15: 2553.525 | Y15: 14674.411 | Z15: 995.056 | AA15: 8559.63 | AB15: 44.651 | AC15: #N/A
... A20: 07/1977 | B20: 7 | C20: 1977 | D20: =VLOOKUP(A20,出口墨西哥!$A$30:$B$630,2,0) -> 4.427 | E20: =VLOOKUP(A20,出口马来西亚!$A$30:$B$630,2,0) -> 253.684 | F20: =VLOOKUP($A20,出口韩国!$A$30:$B$630,2,0) -> 34.133 | G20: =VLOOKUP($A20,出口越南!$A$30:$B$426,2,0) -> #N/A | H20: =VLOOKUP($A20,出口美国!$A$30:$B$630,2,0) -> 284.027 | I20: =VLOOKUP($A20,出口泰国!$A$30:$B$630,2,0) -> 47.259 | J20: =VLOOKUP($A20,出口日本!$A$30:$B$630,2,0) -> 161.005 | K20: =VLOOKUP($A20,出口印度!$A$30:$B$630,2,0) -> 26.541 | L20: =VLOOKUP($A20,出口中国!$A$30:$B$630,2,0) -> 10.295 | M20: =VLOOKUP($A20,出口中国台湾!$A$30:$B$630,2,0) -> 17.78 | N20: =VLOOKUP($A20,出口中国香港特别行政区!$A$30:$B$630,2,0) -> 162.067 | R20: 1992 | S20: 8080.798 | T20: 4187.811 | U20: 1811.162 | V20: 1524.345 | W20: 7856.674 | X20: 6441.794 | Y20: 21778.917 | Z20: 2325.334 | AA20: 12925.408 | AB20: 176.07 | AC20: #N/A
A21: 08/1977 | B21: 8 | C21: 1977 | D21: =VLOOKUP(A21,出口墨西哥!$A$30:$B$630,2,0) -> 5.752 | E21: =VLOOKUP(A21,出口马来西亚!$A$30:$B$630,2,0) -> 258.209 | F21: =VLOOKUP($A21,出口韩国!$A$30:$B$630,2,0) -> 22.305 | G21: =VLOOKUP($A21,出口越南!$A$30:$B$426,2,0) -> #N/A | H21: =VLOOKUP($A21,出口美国!$A$30:$B$630,2,0) -> 293.942 | I21: =VLOOKUP($A21,出口泰国!$A$30:$B$630,2,0) -> 46.77 | J21: =VLOOKUP($A21,出口日本!$A$30:$B$630,2,0) -> 199.345 | K21: =VLOOKUP($A21,出口印度!$A$30:$B$630,2,0) -> 26.677 | L21: =VLOOKUP($A21,出口中国!$A$30:$B$630,2,0) -> 14.665 | M21: =VLOOKUP($A21,出口中国台湾!$A$30:$B$630,2,0) -> 25.492 | N21: =VLOOKUP($A21,出口中国香港特别行政区!$A$30:$B$630,2,0) -> 120.089 | R21: 1993 | S21: 10363.885 | T21: 4641.38 | U21: 3067.51 | V21: 1533.376 | W21: 8921.338 | X21: 6804.936 | Y21: 24291.753 | Z21: 3325.699 | AA21: 16942.164 | AB21: 211.026 | AC21: 1582.449
A22: 09/1977 | B22: 9 | C22: 1977 | D22: =VLOOKUP(A22,出口墨西哥!$A$30:$B$630,2,0) -> 5.722 | E22: =VLOOKUP(A22,出口马来西亚!$A$30:$B$630,2,0) -> 245.142 | F22: =VLOOKUP($A22,出口韩国!$A$30:$B$630,2,0) -> 38.546 | G22: =VLOOKUP($A22,出口越南!$A$30:$B$426,2,0) -> #N/A | H22: =VLOOKUP($A22,出口美国!$A$30:$B$630,2,0) -> 253.813 | I22: =VLOOKUP($A22,出口泰国!$A$30:$B$630,2,0) -> 50.118 | J22: =VLOOKUP($A22,出口日本!$A$30:$B$630,2,0) -> 162.486 | K22: =VLOOKUP($A22,出口印度!$A$30:$B$630,2,0) -> 33.883 | L22: =VLOOKUP($A22,出口中国!$A$30:$B$630,2,0) -> 45.483 | M22: =VLOOKUP($A22,出口中国台湾!$A$30:$B$630,2,0) -> 25.422 | N22: =VLOOKUP($A22,出口中国香港特别行政区!$A$30:$B$630,2,0) -> 136.244 | R22: 1994 | S22: 12814.238 | T22: 5939.545 | U22: 3206.707 | V22: 1928.047 | W22: 10342.562 | X22: 8186.29 | Y22: 27637.014 | Z22: 3870.86 | AA22: 29089.495 | AB22: 311.767 | AC22: 2030.303
A23: 10/1977 | B23: 10 | C23: 1977 | D23: =VLOOKUP(A23,出口墨西哥!$A$30:$B$630,2,0) -> 6.156 | E23: =VLOOKUP(A23,出口马来西亚!$A$30:$B$630,2,0) -> 256.27 | F23: =VLOOKUP($A23,出口韩国!$A$30:$B$630,2,0) -> 21.326 | G23: =VLOOKUP($A23,出口越南!$A$30:$B$426,2,0) -> #N/A | H23: =VLOOKUP($A23,出口美国!$A$30:$B$630,2,0) -> 250.147 | I23: =VLOOKUP($A23,出口泰国!$A$30:$B$630,2,0) -> 43.375 | J23: =VLOOKUP($A23,出口日本!$A$30:$B$630,2,0) -> 166.648 | K23: =VLOOKUP($A23,出口印度!$A$30:$B$630,2,0) -> 46.263 | L23: =VLOOKUP($A23,出口中国!$A$30:$B$630,2,0) -> 9.48 | M23: =VLOOKUP($A23,出口中国台湾!$A$30:$B$630,2,0) -> 31.207 | N23: =VLOOKUP($A23,出口中国香港特别行政区!$A$30:$B$630,2,0) -> 117.762 | R23: 1995 | S23: 14352.172 | T23: 6822.313 | U23: 3910.633 | V23: 2660.992 | W23: 13066.2 | X23: 9671.771 | Y23: 30546.541 | Z23: 4596.539 | AA23: 32124.856 | AB23: 265.288 | AC23: 2537.131
A24: 11/1977 | B24: 11 | C24: 1977 | D24: =VLOOKUP(A24,出口墨西哥!$A$30:$B$630,2,0) -> 4.33 | E24: =VLOOKUP(A24,出口马来西亚!$A$30:$B$630,2,0) -> 255.812 | F24: =VLOOKUP($A24,出口韩国!$A$30:$B$630,2,0) -> 34.793 | G24: =VLOOKUP($A24,出口越南!$A$30:$B$426,2,0) -> #N/A | H24: =VLOOKUP($A24,出口美国!$A$30:$B$630,2,0) -> 273.632 | I24: =VLOOKUP($A24,出口泰国!$A$30:$B$630,2,0) -> 58.392 | J24: =VLOOKUP($A24,出口日本!$A$30:$B$630,2,0) -> 210.441 | K24: =VLOOKUP($A24,出口印度!$A$30:$B$630,2,0) -> 50.688 | L24: =VLOOKUP($A24,出口中国!$A$30:$B$630,2,0) -> 7.68 | M24: =VLOOKUP($A24,出口中国台湾!$A$30:$B$630,2,0) -> 33.192 | N24: =VLOOKUP($A24,出口中国香港特别行政区!$A$30:$B$630,2,0) -> 138.349 | R24: 1996 | S24: 15687.401 | T24: 6869.884 | U24: 4783.948 | V24: 2927.029 | W24: 14454.705 | X24: 10006.161 | Y24: 32446.306 | Z24: 5352.873 | AA24: 31742.891 | AB24: 547.62 | AC24: 2419.715
A25: 12/1977 | B25: 12 | C25: 1977 | D25: =VLOOKUP(A25,出口墨西哥!$A$30:$B$630,2,0) -> 4.767 | E25: =VLOOKUP(A25,出口马来西亚!$A$30:$B$630,2,0) -> 264.161 | F25: =VLOOKUP($A25,出口韩国!$A$30:$B$630,2,0) -> 17.91 | G25: =VLOOKUP($A25,出口越南!$A$30:$B$426,2,0) -> #N/A | H25: =VLOOKUP($A25,出口美国!$A$30:$B$630,2,0) -> 241.788 | I25: =VLOOKUP($A25,出口泰国!$A$30:$B$630,2,0) -> 80.963 | J25: =VLOOKUP($A25,出口日本!$A$30:$B$630,2,0) -> 164.359 | K25: =VLOOKUP($A25,出口印度!$A$30:$B$630,2,0) -> 62.672 | L25: =VLOOKUP($A25,出口中国!$A$30:$B$630,2,0) -> 13.507 | M25: =VLOOKUP($A25,出口中国台湾!$A$30:$B$630,2,0) -> 28.866 | N25: =VLOOKUP($A25,出口中国香港特别行政区!$A$30:$B$630,2,0) -> 119.69 | R25: 1997 | S25: 17848.433 | T25: 8367.457 | U25: 6037.551 | V25: 3297.488 | W25: 13124.508 | X25: 8532.436 | Y25: 34117.494 | Z25: 5482.957 | AA25: 32404.824 | AB25: 723.141 | AC25: 2473.424
A26: 01/1978 | B26: 1 | C26: 1978 | D26: =VLOOKUP(A26,出口墨西哥!$A$30:$B$630,2,0) -> 3.602 | E26: =VLOOKUP(A26,出口马来西亚!$A$30:$B$630,2,0) -> 242.391 | F26: =VLOOKUP($A26,出口韩国!$A$30:$B$630,2,0) -> 32.217 | G26: =VLOOKUP($A26,出口越南!$A$30:$B$426,2,0) -> #N/A | H26: =VLOOKUP($A26,出口美国!$A$30:$B$630,2,0) -> 265.378 | I26: =VLOOKUP($A26,出口泰国!$A$30:$B$630,2,0) -> 53.527 | J26: =VLOOKUP($A26,出口日本!$A$30:$B$630,2,0) -> 165.365 | K26: =VLOOKUP($A26,出口印度!$A$30:$B$630,2,0) -> 125.444 | L26: =VLOOKUP($A26,出口中国!$A$30:$B$630,2,0) -> 6.058 | M26: =VLOOKUP($A26,出口中国台湾!$A$30:$B$630,2,0) -> 32.65 | N26: =VLOOKUP($A26,出口中国香港特别行政区!$A$30:$B$630,2,0) -> 114.687 | R26: 1998 | S26: 15418.305 | T26: 7928.742 | U26: 6794.336 | V26: 4073.04 | W26: 12089.672 | X26: 7037.22 | Y26: 36505.67 | Z26: 4291.082 | AA26: 27998.884 | AB26: 857.324 | AC26: 2530.993
A27: 02/1978 | B27: 2 | C27: 1978 | D27: =VLOOKUP(A27,出口墨西哥!$A$30:$B$630,2,0) -> 5.073 | E27: =VLOOKUP(A27,出口马来西亚!$A$30:$B$630,2,0) -> 192.937 | F27: =VLOOKUP($A27,出口韩国!$A$30:$B$630,2,0) -> 18.497 | G27: =VLOOKUP($A27,出口越南!$A$30:$B$426,2,0) -> #N/A | H27: =VLOOKUP($A27,出口美国!$A$30:$B$630,2,0) -> 158.395 | I27: =VLOOKUP($A27,出口泰国!$A$30:$B$630,2,0) -> 66.892 | J27: =VLOOKUP($A27,出口日本!$A$30:$B$630,2,0) -> 119.097 | K27: =VLOOKUP($A27,出口印度!$A$30:$B$630,2,0) -> 76.773 | L27: =VLOOKUP($A27,出口中国!$A$30:$B$630,2,0) -> 7.015 | M27: =VLOOKUP($A27,出口中国台湾!$A$30:$B$630,2,0) -> 19.58 | N27: =VLOOKUP($A27,出口中国香港特别行政区!$A$30:$B$630,2,0) -> 96.338 | R27: 1999 | S27: 14915.222 | T27: 9477.27 | U27: 6642.732 | V27: 4243.315 | W27: 14420.741 | X27: 8535.94 | Y27: 37214.765 | Z27: 6027.265 | AA27: 32163.68 | AB27: 1175.955 | AC27: 2532.478
A28: 03/1978 | B28: 3 | C28: 1978 | D28: =VLOOKUP(A28,出口墨西哥!$A$30:$B$630,2,0) -> 3.351 | E28: =VLOOKUP(A28,出口马来西亚!$A$30:$B$630,2,0) -> 273.968 | F28: =VLOOKUP($A28,出口韩国!$A$30:$B$630,2,0) -> 25.716 | G28: =VLOOKUP($A28,出口越南!$A$30:$B$426,2,0) -> #N/A | H28: =VLOOKUP($A28,出口美国!$A$30:$B$630,2,0) -> 349.493 | I28: =VLOOKUP($A28,出口泰国!$A$30:$B$630,2,0) -> 77.515 | J28: =VLOOKUP($A28,出口日本!$A$30:$B$630,2,0) -> 212.777 | K28: =VLOOKUP($A28,出口印度!$A$30:$B$630,2,0) -> 41.762 | L28: =VLOOKUP($A28,出口中国!$A$30:$B$630,2,0) -> 8.615 | M28: =VLOOKUP($A28,出口中国台湾!$A$30:$B$630,2,0) -> 28.935 | N28: =VLOOKUP($A28,出口中国香港特别行政区!$A$30:$B$630,2,0) -> 138.46 | R28: 2000 | S28: 18704.919 | T28: 14195.461 | U28: 9285.006 | V28: 4803.697 | W28: 17948.714 | X28: 10121.668 | Y28: 41188.859 | Z28: 8478.923 | AA28: 43189.831 | AB28: 1432.396 | AC28: 3610.514
A29: 04/1978 | B29: 4 | C29: 1978 | D29: =VLOOKUP(A29,出口墨西哥!$A$30:$B$630,2,0) -> 5.116 | E29: =VLOOKUP(A29,出口马来西亚!$A$30:$B$630,2,0) -> 257.19 | F29: =VLOOKUP($A29,出口韩国!$A$30:$B$630,2,0) -> 28.76 | G29: =VLOOKUP($A29,出口越南!$A$30:$B$426,2,0) -> #N/A | H29: =VLOOKUP($A29,出口美国!$A$30:$B$630,2,0) -> 331.028 | I29: =VLOOKUP($A29,出口泰国!$A$30:$B$630,2,0) -> 82.196 | J29: =VLOOKUP($A29,出口日本!$A$30:$B$630,2,0) -> 178.061 | K29: =VLOOKUP($A29,出口印度!$A$30:$B$630,2,0) -> 41.527 | L29: =VLOOKUP($A29,出口中国!$A$30:$B$630,2,0) -> 14.418 | M29: =VLOOKUP($A29,出口中国台湾!$A$30:$B$630,2,0) -> 24.811 | N29: =VLOOKUP($A29,出口中国香港特别行政区!$A$30:$B$630,2,0) -> 144.094 | R29: 2001 | S29: 19373.73 | T29: 11219.478 | U29: 9545.024 | V29: 4872.766 | W29: 16712.252 | X29: 9486.632 | Y29: 33533.585 | Z29: 8391.728 | AA29: 37821.462 | AB29: 1319.181 | AC29: 3769.264
A30: 05/1978 | B30: 5 | C30: 1978 | D30: =VLOOKUP(A30,出口墨西哥!$A$30:$B$630,2,0) -> 4.884 | E30: =VLOOKUP(A30,出口马来西亚!$A$30:$B$630,2,0) -> 263.83 | F30: =VLOOKUP($A30,出口韩国!$A$30:$B$630,2,0) -> 20.973 | G30: =VLOOKUP($A30,出口越南!$A$30:$B$426,2,0) -> #N/A | H30: =VLOOKUP($A30,出口美国!$A$30:$B$630,2,0) -> 351.432 | I30: =VLOOKUP($A30,出口泰国!$A$30:$B$630,2,0) -> 49.678 | J30: =VLOOKUP($A30,出口日本!$A$30:$B$630,2,0) -> 163.591 | K30: =VLOOKUP($A30,出口印度!$A$30:$B$630,2,0) -> 25.008 | L30: =VLOOKUP($A30,出口中国!$A$30:$B$630,2,0) -> 9.008 | M30: =VLOOKUP($A30,出口中国台湾!$A$30:$B$630,2,0) -> 20.345 | N30: =VLOOKUP($A30,出口中国香港特别行政区!$A$30:$B$630,2,0) -> 119.444 | R30: 2002 | S30: 20495.669 | T30: 11086.75 | U30: 12268.104 | V30: 5853.976 | W30: 15990.162 | X30: 10389.424 | Y30: 32935.274 | Z30: 9465.112 | AA30: 39409.743 | AB30: 1331.241 | AC30: 3729.192
A31: 06/1978 | B31: 6 | C31: 1978 | D31: =VLOOKUP(A31,出口墨西哥!$A$30:$B$630,2,0) -> 4.188 | E31: =VLOOKUP(A31,出口马来西亚!$A$30:$B$630,2,0) -> 279.919 | F31: =VLOOKUP($A31,出口韩国!$A$30:$B$630,2,0) -> 33.029 | G31: =VLOOKUP($A31,出口越南!$A$30:$B$426,2,0) -> #N/A | H31: =VLOOKUP($A31,出口美国!$A$30:$B$630,2,0) -> 273.868 | I31: =VLOOKUP($A31,出口泰国!$A$30:$B$630,2,0) -> 67.457 | J31: =VLOOKUP($A31,出口日本!$A$30:$B$630,2,0) -> 188.807 | K31: =VLOOKUP($A31,出口印度!$A$30:$B$630,2,0) -> 27.757 | L31: =VLOOKUP($A31,出口中国!$A$30:$B$630,2,0) -> 5.383 | M31: =VLOOKUP($A31,出口中国台湾!$A$30:$B$630,2,0) -> 23.491 | N31: =VLOOKUP($A31,出口中国香港特别行政区!$A$30:$B$630,2,0) -> 139.312 | R31: 2003 | S31: 25174.6 | T31: 12011.8 | U31: 17638.1 | V31: 5418.8 | W31: 16875.5 | X31: 10746 | Y31: 33460 | Z31: 10581.3 | AA31: 40237.3 | AB31: 1251.5 | AC31: 4194.4
A32: 07/1978 | B32: 7 | C32: 1978 | D32: =VLOOKUP(A32,出口墨西哥!$A$30:$B$630,2,0) -> 4.712 | E32: =VLOOKUP(A32,出口马来西亚!$A$30:$B$630,2,0) -> 277.65 | F32: =VLOOKUP($A32,出口韩国!$A$30:$B$630,2,0) -> 31.136 | G32: =VLOOKUP($A32,出口越南!$A$30:$B$426,2,0) -> #N/A | H32: =VLOOKUP($A32,出口美国!$A$30:$B$630,2,0) -> 283.74 | I32: =VLOOKUP($A32,出口泰国!$A$30:$B$630,2,0) -> 62.265 | J32: =VLOOKUP($A32,出口日本!$A$30:$B$630,2,0) -> 196.271 | K32: =VLOOKUP($A32,出口印度!$A$30:$B$630,2,0) -> 28.849 | L32: =VLOOKUP($A32,出口中国!$A$30:$B$630,2,0) -> 9.794 | M32: =VLOOKUP($A32,出口中国台湾!$A$30:$B$630,2,0) -> 33.483 | N32: =VLOOKUP($A32,出口中国香港特别行政区!$A$30:$B$630,2,0) -> 143.419 | R32: 2004 | S32: 29807.1 | T32: 14075.1 | U32: 25972.2 | V32: 7145.4 | W32: 19533.2 | X32: 13086.2 | Y32: 37500.7 | Z32: 12495.2 | AA32: 46323.8 | AB32: 1416 | AC32: 5366.9
... A54: 05/1980 | B54: 5 | C54: 1980 | D54: =VLOOKUP(A54,出口墨西哥!$A$30:$B$630,2,0) -> 5.53 | E54: =VLOOKUP(A54,出口马来西亚!$A$30:$B$630,2,0) -> 520.958 | F54: =VLOOKUP($A54,出口韩国!$A$30:$B$630,2,0) -> 60.962 | G54: =VLOOKUP($A54,出口越南!$A$30:$B$426,2,0) -> #N/A | H54: =VLOOKUP($A54,出口美国!$A$30:$B$630,2,0) -> 480.739 | I54: =VLOOKUP($A54,出口泰国!$A$30:$B$630,2,0) -> 167.919 | J54: =VLOOKUP($A54,出口日本!$A$30:$B$630,2,0) -> 334.804 | K54: =VLOOKUP($A54,出口印度!$A$30:$B$630,2,0) -> 123.815 | L54: =VLOOKUP($A54,出口中国!$A$30:$B$630,2,0) -> 47.836 | M54: =VLOOKUP($A54,出口中国台湾!$A$30:$B$630,2,0) -> 54.124 | N54: =VLOOKUP($A54,出口中国香港特别行政区!$A$30:$B$630,2,0) -> 271.961 | R54: 2026 | S54: 8154 | T54: 11214.6 | U54: 7443.3 | V54: 2162.6 | W54: 2247 | X54: 6171.1 | Y54: 5856.3 | Z54: 3029.5 | AA54: 6071.3 | AB54: 2358.1 | AC54: 2952.2
A55: 06/1980 | B55: 6 | C55: 1980 | D55: =VLOOKUP(A55,出口墨西哥!$A$30:$B$630,2,0) -> 6.835 | E55: =VLOOKUP(A55,出口马来西亚!$A$30:$B$630,2,0) -> 546.381 | F55: =VLOOKUP($A55,出口韩国!$A$30:$B$630,2,0) -> 31.172 | G55: =VLOOKUP($A55,出口越南!$A$30:$B$426,2,0) -> #N/A | H55: =VLOOKUP($A55,出口美国!$A$30:$B$630,2,0) -> 385.128 | I55: =VLOOKUP($A55,出口泰国!$A$30:$B$630,2,0) -> 122.18 | J55: =VLOOKUP($A55,出口日本!$A$30:$B$630,2,0) -> 310.248 | K55: =VLOOKUP($A55,出口印度!$A$30:$B$630,2,0) -> 79.452 | L55: =VLOOKUP($A55,出口中国!$A$30:$B$630,2,0) -> 43.545 | M55: =VLOOKUP($A55,出口中国台湾!$A$30:$B$630,2,0) -> 72.217 | N55: =VLOOKUP($A55,出口中国香港特别行政区!$A$30:$B$630,2,0) -> 297.769 | R55: Grand Total | S55: 1550485.4 | T55: 635549.09 | U55: 1480928.6 | V55: 409827.08 | W55: 745024.79 | X55: 602118.1 | Y55: 1447990.3 | Z55: 552608.96 | AA55: 1787081.2 | AB55: 67385.559 | AC55: #N/A
A56: 07/1980 | B56: 7 | C56: 1980 | D56: =VLOOKUP(A56,出口墨西哥!$A$30:$B$630,2,0) -> 7.067 | E56: =VLOOKUP(A56,出口马来西亚!$A$30:$B$630,2,0) -> 570.137 | F56: =VLOOKUP($A56,出口韩国!$A$30:$B$630,2,0) -> 35.644 | G56: =VLOOKUP($A56,出口越南!$A$30:$B$426,2,0) -> #N/A | H56: =VLOOKUP($A56,出口美国!$A$30:$B$630,2,0) -> 550 | I56: =VLOOKUP($A56,出口泰国!$A$30:$B$630,2,0) -> 182.545 | J56: =VLOOKUP($A56,出口日本!$A$30:$B$630,2,0) -> 354.691 | K56: =VLOOKUP($A56,出口印度!$A$30:$B$630,2,0) -> 46.953 | L56: =VLOOKUP($A56,出口中国!$A$30:$B$630,2,0) -> 47.307 | M56: =VLOOKUP($A56,出口中国台湾!$A$30:$B$630,2,0) -> 59.257 | N56: =VLOOKUP($A56,出口中国香港特别行政区!$A$30:$B$630,2,0) -> 252.652
A57: 08/1980 | B57: 8 | C57: 1980 | D57: =VLOOKUP(A57,出口墨西哥!$A$30:$B$630,2,0) -> 7.693 | E57: =VLOOKUP(A57,出口马来西亚!$A$30:$B$630,2,0) -> 519.258 | F57: =VLOOKUP($A57,出口韩国!$A$30:$B$630,2,0) -> 30.359 | G57: =VLOOKUP($A57,出口越南!$A$30:$B$426,2,0) -> #N/A | H57: =VLOOKUP($A57,出口美国!$A$30:$B$630,2,0) -> 366.257 | I57: =VLOOKUP($A57,出口泰国!$A$30:$B$630,2,0) -> 126.401 | J57: =VLOOKUP($A57,出口日本!$A$30:$B$630,2,0) -> 179.217 | K57: =VLOOKUP($A57,出口印度!$A$30:$B$630,2,0) -> 55.53 | L57: =VLOOKUP($A57,出口中国!$A$30:$B$630,2,0) -> 33.786 | M57: =VLOOKUP($A57,出口中国台湾!$A$30:$B$630,2,0) -> 69.899 | N57: =VLOOKUP($A57,出口中国香港特别行政区!$A$30:$B$630,2,0) -> 309.333
A58: 09/1980 | B58: 9 | C58: 1980 | D58: =VLOOKUP(A58,出口墨西哥!$A$30:$B$630,2,0) -> 7.485 | E58: =VLOOKUP(A58,出口马来西亚!$A$30:$B$630,2,0) -> 544.241 | F58: =VLOOKUP($A58,出口韩国!$A$30:$B$630,2,0) -> 68.469 | G58: =VLOOKUP($A58,出口越南!$A$30:$B$426,2,0) -> #N/A | H58: =VLOOKUP($A58,出口美国!$A$30:$B$630,2,0) -> 390.327 | I58: =VLOOKUP($A58,出口泰国!$A$30:$B$630,2,0) -> 94.415 | J58: =VLOOKUP($A58,出口日本!$A$30:$B$630,2,0) -> 237.398 | K58: =VLOOKUP($A58,出口印度!$A$30:$B$630,2,0) -> 49.046 | L58: =VLOOKUP($A58,出口中国!$A$30:$B$630,2,0) -> 49.856 | M58: =VLOOKUP($A58,出口中国台湾!$A$30:$B$630,2,0) -> 65.734 | N58: =VLOOKUP($A58,出口中国香港特别行政区!$A$30:$B$630,2,0) -> 324.486
A59: 10/1980 | B59: 10 | C59: 1980 | D59: =VLOOKUP(A59,出口墨西哥!$A$30:$B$630,2,0) -> 6.827 | E59: =VLOOKUP(A59,出口马来西亚!$A$30:$B$630,2,0) -> 586.154 | F59: =VLOOKUP($A59,出口韩国!$A$30:$B$630,2,0) -> 27.332 | G59: =VLOOKUP($A59,出口越南!$A$30:$B$426,2,0) -> #N/A | H59: =VLOOKUP($A59,出口美国!$A$30:$B$630,2,0) -> 524.568 | I59: =VLOOKUP($A59,出口泰国!$A$30:$B$630,2,0) -> 140.672 | J59: =VLOOKUP($A59,出口日本!$A$30:$B$630,2,0) -> 232.811 | K59: =VLOOKUP($A59,出口印度!$A$30:$B$630,2,0) -> 75.748 | L59: =VLOOKUP($A59,出口中国!$A$30:$B$630,2,0) -> 56.653 | M59: =VLOOKUP($A59,出口中国台湾!$A$30:$B$630,2,0) -> 41.664 | N59: =VLOOKUP($A59,出口中国香港特别行政区!$A$30:$B$630,2,0) -> 214.504
A60: 11/1980 | B60: 11 | C60: 1980 | D60: =VLOOKUP(A60,出口墨西哥!$A$30:$B$630,2,0) -> 6.057 | E60: =VLOOKUP(A60,出口马来西亚!$A$30:$B$630,2,0) -> 520.14 | F60: =VLOOKUP($A60,出口韩国!$A$30:$B$630,2,0) -> 24.324 | G60: =VLOOKUP($A60,出口越南!$A$30:$B$426,2,0) -> #N/A | H60: =VLOOKUP($A60,出口美国!$A$30:$B$630,2,0) -> 404.4 | I60: =VLOOKUP($A60,出口泰国!$A$30:$B$630,2,0) -> 128.71 | J60: =VLOOKUP($A60,出口日本!$A$30:$B$630,2,0) -> 316.15 | K60: =VLOOKUP($A60,出口印度!$A$30:$B$630,2,0) -> 49.6 | L60: =VLOOKUP($A60,出口中国!$A$30:$B$630,2,0) -> 36.136 | M60: =VLOOKUP($A60,出口中国台湾!$A$30:$B$630,2,0) -> 57.447 | N60: =VLOOKUP($A60,出口中国香港特别行政区!$A$30:$B$630,2,0) -> 346.696
A61: 12/1980 | B61: 12 | C61: 1980 | D61: =VLOOKUP(A61,出口墨西哥!$A$30:$B$630,2,0) -> 6.597 | E61: =VLOOKUP(A61,出口马来西亚!$A$30:$B$630,2,0) -> 590.028 | F61: =VLOOKUP($A61,出口韩国!$A$30:$B$630,2,0) -> 47.238 | G61: =VLOOKUP($A61,出口越南!$A$30:$B$426,2,0) -> #N/A | H61: =VLOOKUP($A61,出口美国!$A$30:$B$630,2,0) -> 467.396 | I61: =VLOOKUP($A61,出口泰国!$A$30:$B$630,2,0) -> 207.19 | J61: =VLOOKUP($A61,出口日本!$A$30:$B$630,2,0) -> 220.533 | K61: =VLOOKUP($A61,出口印度!$A$30:$B$630,2,0) -> 91.549 | L61: =VLOOKUP($A61,出口中国!$A$30:$B$630,2,0) -> 103.227 | M61: =VLOOKUP($A61,出口中国台湾!$A$30:$B$630,2,0) -> 48.32 | N61: =VLOOKUP($A61,出口中国香港特别行政区!$A$30:$B$630,2,0) -> 295.023
A62: 01/1981 | B62: 1 | C62: 1981 | D62: =VLOOKUP(A62,出口墨西哥!$A$30:$B$630,2,0) -> 5.622 | E62: =VLOOKUP(A62,出口马来西亚!$A$30:$B$630,2,0) -> 578.728 | F62: =VLOOKUP($A62,出口韩国!$A$30:$B$630,2,0) -> 47.48 | G62: =VLOOKUP($A62,出口越南!$A$30:$B$426,2,0) -> #N/A | H62: =VLOOKUP($A62,出口美国!$A$30:$B$630,2,0) -> 370.584 | I62: =VLOOKUP($A62,出口泰国!$A$30:$B$630,2,0) -> 199.663 | J62: =VLOOKUP($A62,出口日本!$A$30:$B$630,2,0) -> 291.727 | K62: =VLOOKUP($A62,出口印度!$A$30:$B$630,2,0) -> 169.234 | L62: =VLOOKUP($A62,出口中国!$A$30:$B$630,2,0) -> 36.175 | M62: =VLOOKUP($A62,出口中国台湾!$A$30:$B$630,2,0) -> 67.938 | N62: =VLOOKUP($A62,出口中国香港特别行政区!$A$30:$B$630,2,0) -> 402.692
A63: 02/1981 | B63: 2 | C63: 1981 | D63: =VLOOKUP(A63,出口墨西哥!$A$30:$B$630,2,0) -> 5.192 | E63: =VLOOKUP(A63,出口马来西亚!$A$30:$B$630,2,0) -> 432.41 | F63: =VLOOKUP($A63,出口韩国!$A$30:$B$630,2,0) -> 30.385 | G63: =VLOOKUP($A63,出口越南!$A$30:$B$426,2,0) -> #N/A | H63: =VLOOKUP($A63,出口美国!$A$30:$B$630,2,0) -> 378.264 | I63: =VLOOKUP($A63,出口泰国!$A$30:$B$630,2,0) -> 231.659 | J63: =VLOOKUP($A63,出口日本!$A$30:$B$630,2,0) -> 304.739 | K63: =VLOOKUP($A63,出口印度!$A$30:$B$630,2,0) -> 97.283 | L63: =VLOOKUP($A63,出口中国!$A$30:$B$630,2,0) -> 32.123 | M63: =VLOOKUP($A63,出口中国台湾!$A$30:$B$630,2,0) -> 74.57 | N63: =VLOOKUP($A63,出口中国香港特别行政区!$A$30:$B$630,2,0) -> 235.627
A64: 03/1981 | B64: 3 | C64: 1981 | D64: =VLOOKUP(A64,出口墨西哥!$A$30:$B$630,2,0) -> 9.792 | E64: =VLOOKUP(A64,出口马来西亚!$A$30:$B$630,2,0) -> 573.2 | F64: =VLOOKUP($A64,出口韩国!$A$30:$B$630,2,0) -> 50.863 | G64: =VLOOKUP($A64,出口越南!$A$30:$B$426,2,0) -> #N/A | H64: =VLOOKUP($A64,出口美国!$A$30:$B$630,2,0) -> 476.57 | I64: =VLOOKUP($A64,出口泰国!$A$30:$B$630,2,0) -> 210.814 | J64: =VLOOKUP($A64,出口日本!$A$30:$B$630,2,0) -> 301.087 | K64: =VLOOKUP($A64,出口印度!$A$30:$B$630,2,0) -> 95.676 | L64: =VLOOKUP($A64,出口中国!$A$30:$B$630,2,0) -> 30.138 | M64: =VLOOKUP($A64,出口中国台湾!$A$30:$B$630,2,0) -> 54.736 | N64: =VLOOKUP($A64,出口中国香港特别行政区!$A$30:$B$630,2,0) -> 279.362
A65: 04/1981 | B65: 4 | C65: 1981 | D65: =VLOOKUP(A65,出口墨西哥!$A$30:$B$630,2,0) -> 4.087 | E65: =VLOOKUP(A65,出口马来西亚!$A$30:$B$630,2,0) -> 574.717 | F65: =VLOOKUP($A65,出口韩国!$A$30:$B$630,2,0) -> 37.044 | G65: =VLOOKUP($A65,出口越南!$A$30:$B$426,2,0) -> #N/A | H65: =VLOOKUP($A65,出口美国!$A$30:$B$630,2,0) -> 509.415 | I65: =VLOOKUP($A65,出口泰国!$A$30:$B$630,2,0) -> 188.449 | J65: =VLOOKUP($A65,出口日本!$A$30:$B$630,2,0) -> 314.068 | K65: =VLOOKUP($A65,出口印度!$A$30:$B$630,2,0) -> 119.597 | L65: =VLOOKUP($A65,出口中国!$A$30:$B$630,2,0) -> 29.312 | M65: =VLOOKUP($A65,出口中国台湾!$A$30:$B$630,2,0) -> 41.873 | N65: =VLOOKUP($A65,出口中国香港特别行政区!$A$30:$B$630,2,0) -> 297.485
...

Sheet 出口墨西哥
B1: 出口：墨西哥
A2: 区域 | B2: 新加坡
A3: 次国家
A4: 频率 | B4: 月
A5: 单位 | B5: 百万新加坡元
A6: 数据来源 | B6: Enterprise Singapore
A7: 状态 | B7: 继续
A8: 数列ID | B8: 36424201 (SJFSE)
A9: SR码 | B9: SR520858
A10: 贸易代码
A11: 助记符
A12: 函数说明
A13: 首次观测日期 | B13: 01/1976
A14: 最后观测日期 | B14: 01/2026
A15: 最后更新时间 | B15: 16/02/2026
A16: 数列备注
A17: 建议
A18: 平均 MEAN | B18: 112.12239434276204
A19: 方差 | B19: 36449.067613842584
A20: 标准差 | B20: 190.91639
A21: 偏度 | B21: 5.773927052639332
A22: 峰度 | B22: 48.853523
A23: 变异系数 | B23: 1.7027498403392012
A24: 最小 | B24: 0.477
A25: 最大 | B25: 2358.1
A26: 中位数 | B26: 84.089
A27: 总和 SUM | B27: 67385.55899999998
A28: 减 SUBTRACT | B28: -2357.623
A29: 参照期间 | B29: 601
A30: 01/1976 | B30: 4.421
A31: 02/1976 | B31: 2.171
A32: 03/1976 | B32: 4.053
A33: 04/1976 | B33: 3.836
A34: 05/1976 | B34: 4.832
A35: 06/1976 | B35: 2.452
A36: 07/1976 | B36: 3.999
A37: 08/1976 | B37: 1.884
A38: 09/1976 | B38: 4.9
A39: 10/1976 | B39: 3.081
... A630: 01/2026 | B630: 2358.1

Sheet 出口马来西亚
B1: 出口：马来西亚
A2: 区域 | B2: 新加坡
A3: 次国家
A4: 频率 | B4: 月
A5: 单位 | B5: 百万新加坡元
A6: 数据来源 | B6: Enterprise Singapore
A7: 状态 | B7: 继续
A8: 数列ID | B8: 36422301 (SJFF)
A9: SR码 | B9: SR520890
A10: 贸易代码
A11: 助记符
A12: 函数说明
A13: 首次观测日期 | B13: 01/1976
A14: 最后观测日期 | B14: 01/2026
A15: 最后更新时间 | B15: 16/02/2026
A16: 数列备注 | B16: [COVID-19-IMPACT]
A17: 建议
A18: 平均 MEAN | B18: 2973.5127853577355
A19: 方差 | B19: 3790135.881120139
A20: 标准差 | B20: 1946.8271318019324
A21: 偏度 | B21: 0.018672168323986126
A22: 峰度 | B22: -1.3792528
A23: 变异系数 | B23: 0.6547229732418032
A24: 最小 | B24: 171.755
A25: 最大 | B25: 7189.4
A26: 中位数 | B26: 3135.71
A27: 总和 SUM | B27: 1787081.1840000018
A28: 减 SUBTRACT | B28: -7017.645
A29: 参照期间 | B29: 601
A30: 01/1976 | B30: 180.289
A31: 02/1976 | B31: 171.755
A32: 03/1976 | B32: 201.753
A33: 04/1976 | B33: 207.398
A34: 05/1976 | B34: 188.857
A35: 06/1976 | B35: 196.107
A36: 07/1976 | B36: 231.574
A37: 08/1976 | B37: 201.877
A38: 09/1976 | B38: 226.243
A39: 10/1976 | B39: 216.321
... A630: 01/2026 | B630: 6071.3

Sheet 出口韩国
B1: 出口：韩国
A2: 区域 | B2: 新加坡
A3: 次国家
A4: 频率 | B4: 月
A5: 单位 | B5: 百万新加坡元
A6: 数据来源 | B6: Enterprise Singapore
A7: 状态 | B7: 继续
A8: 数列ID | B8: 36422901 (SJFM)
A9: SR码 | B9: SR520888
A10: 贸易代码
A11: 助记符
A12: 函数说明
A13: 首次观测日期 | B13: 01/1976
A14: 最后观测日期 | B14: 01/2026
A15: 最后更新时间 | B15: 16/02/2026
A16: 数列备注
A17: 建议
A18: 平均 MEAN | B18: 919.4824708818645
A19: 方差 | B19: 676762.8889279425
A20: 标准差 | B20: 822.6559967130505
A21: 偏度 | B21: 0.49068451356299286
A22: 峰度 | B22: -1.0863307
A23: 变异系数 | B23: 0.8946945948018467
A24: 最小 | B24: 10.344
A25: 最大 | B25: 3083
A26: 中位数 | B26: 706.575
A27: 总和 SUM | B27: 552608.9650000003
A28: 减 SUBTRACT | B28: -3072.656
A29: 参照期间 | B29: 601
A30: 01/1976 | B30: 10.344
A31: 02/1976 | B31: 10.413
A32: 03/1976 | B32: 14.527
A33: 04/1976 | B33: 11.577
A34: 05/1976 | B34: 13.667
A35: 06/1976 | B35: 15.814
A36: 07/1976 | B36: 16.554
A37: 08/1976 | B37: 18.734
A38: 09/1976 | B38: 17.039
A39: 10/1976 | B39: 18.295
... A630: 01/2026 | B630: 3029.5

Sheet 出口越南
B1: 出口：越南
A2: 区域 | B2: 新加坡
A3: 次国家
A4: 频率 | B4: 月
A5: 单位 | B5: 百万新加坡元
A6: 数据来源 | B6: Enterprise Singapore
A7: 状态 | B7: 继续
A8: 数列ID | B8: 76194902 (SJCUBX)
A9: SR码 | B9: SR2328678
A10: 贸易代码
A11: 助记符
A12: 函数说明
A13: 首次观测日期 | B13: 01/1993
A14: 最后观测日期 | B14: 01/2026
A15: 最后更新时间 | B15: 16/02/2026
A16: 数列备注
A17: 建议
A18: 平均 MEAN | B18: 929.9853
A19: 方差 | B19: 408389.7734543409
A20: 标准差 | B20: 639.0538110788018
A21: 偏度 | B21: 0.4722284339699079
A22: 峰度 | B22: -0.71942399
A23: 变异系数 | B23: 0.6871654992641149
A24: 最小 | B24: 102.452
A25: 最大 | B25: 2952.2
A26: 中位数 | B26: 893.9
A27: 总和 SUM | B27: 369204.1630000001
A28: 减 SUBTRACT | B28: -2849.748
A29: 参照期间 | B29: 397
A30: 01/1993 | B30: 110
A31: 02/1993 | B31: 140.285
A32: 03/1993 | B32: 126.025
A33: 04/1993 | B33: 155.589
A34: 05/1993 | B34: 131.089
A35: 06/1993 | B35: 138.692
A36: 07/1993 | B36: 102.452
A37: 08/1993 | B37: 102.684
A38: 09/1993 | B38: 133.035
A39: 10/1993 | B39: 119.838
... A426: 01/2026 | B426: 2952.2

Sheet 出口美国
B1: 出口：美国
A2: 区域 | B2: 新加坡
A3: 次国家
A4: 频率 | B4: 月
A5: 单位 | B5: 百万新加坡元
A6: 数据来源 | B6: Enterprise Singapore
A7: 状态 | B7: 继续
A8: 数列ID | B8: 36423101 (SJFQ)
A9: SR码 | B9: SR520859
A10: 贸易代码
A11: 助记符
A12: 函数说明
A13: 首次观测日期 | B13: 01/1976
A14: 最后观测日期 | B14: 01/2026
A15: 最后更新时间 | B15: 16/02/2026
A16: 数列备注 | B16: [COVID-19-IMPACT]
A17: 建议
A18: 平均 MEAN | B18: 2409.301730449248
A19: 方差 | B19: 1947705.4151068814
A20: 标准差 | B20: 1395.6021693544624
A21: 偏度 | B21: 0.4404978377953158
A22: 峰度 | B22: 0.19080757973485696
A23: 变异系数 | B23: 0.5792558697470543
A24: 最小 | B24: 151.791
A25: 最大 | B25: 7839.8
A26: 中位数 | B26: 2456.7
A27: 总和 SUM | B27: 1447990.3399999999
A28: 减 SUBTRACT | B28: -7688.009
A29: 参照期间 | B29: 601
A30: 01/1976 | B30: 244.148
A31: 02/1976 | B31: 151.791
A32: 03/1976 | B32: 193.48
A33: 04/1976 | B33: 161.726
A34: 05/1976 | B34: 191.72
A35: 06/1976 | B35: 195.342
A36: 07/1976 | B36: 229.319
A37: 08/1976 | B37: 175.253
A38: 09/1976 | B38: 215.515
A39: 10/1976 | B39: 201.301
... A630: 01/2026 | B630: 5856.3

Sheet 出口泰国
B1: 出口：泰国
A2: 区域 | B2: 新加坡
A3: 次国家
A4: 频率 | B4: 月
A5: 单位 | B5: 百万新加坡元
A6: 数据来源 | B6: Enterprise Singapore
A7: 状态 | B7: 继续
A8: 数列ID | B8: 36422201 (SJFE)
A9: SR码 | B9: SR520895
A10: 贸易代码
A11: 助记符
A12: 函数说明
A13: 首次观测日期 | B13: 01/1976
A14: 最后观测日期 | B14: 01/2026
A15: 最后更新时间 | B15: 16/02/2026
A16: 数列备注
A17: 建议
A18: 平均 MEAN | B18: 1001.860394342761
A19: 方差 | B19: 577840.1911022258
A20: 标准差 | B20: 760.1580040374671
A21: 偏度 | B21: 1.1327640317769012
A22: 峰度 | B22: 3.819732785699853
A23: 变异系数 | B23: 0.7587464364594878
A24: 最小 | B24: 30.686
A25: 最大 | B25: 6171.1
A26: 中位数 | B26: 833.188
A27: 总和 SUM | B27: 602118.0969999996
A28: 减 SUBTRACT | B28: -6140.414
A29: 参照期间 | B29: 601
A30: 01/1976 | B30: 44.796
A31: 02/1976 | B31: 31.867
A32: 03/1976 | B32: 48.372
A33: 04/1976 | B33: 52.854
A34: 05/1976 | B34: 49.975
A35: 06/1976 | B35: 34.262
A36: 07/1976 | B36: 35.561
A37: 08/1976 | B37: 33.179
A38: 09/1976 | B38: 41.163
A39: 10/1976 | B39: 32.526
... A630: 01/2026 | B630: 6171.1

Sheet 出口日本
B1: 出口：日本
A2: 区域 | B2: 新加坡
A3: 次国家
A4: 频率 | B4: 月
A5: 单位 | B5: 百万新加坡元
A6: 数据来源 | B6: Enterprise Singapore
A7: 状态 | B7: 继续
A8: 数列ID | B8: 36422501 (SJFH)
A9: SR码 | B9: SR520887
A10: 贸易代码
A11: 助记符
A12: 函数说明
A13: 首次观测日期 | B13: 01/1976
A14: 最后观测日期 | B14: 01/2026
A15: 最后更新时间 | B15: 16/02/2026
A16: 数列备注
A17: 建议
A18: 平均 MEAN | B18: 1239.6419201331119
A19: 方差 | B19: 488274.1408918265
A20: 标准差 | B20: 698.7661560864453
A21: 偏度 | B21: -0.10086164
A22: 峰度 | B22: -1.3855716
A23: 变异系数 | B23: 0.5636838709128297
A24: 最小 | B24: 104.178
A25: 最大 | B25: 2673.3
A26: 中位数 | B26: 1313
A27: 总和 SUM | B27: 745024.7940000002
A28: 减 SUBTRACT | B28: -2569.122
A29: 参照期间 | B29: 601
A30: 01/1976 | B30: 130.744
A31: 02/1976 | B31: 107.053
A32: 03/1976 | B32: 130.205
A33: 04/1976 | B33: 135.849
A34: 05/1976 | B34: 142.944
A35: 06/1976 | B35: 104.178
A36: 07/1976 | B36: 162.027
A37: 08/1976 | B37: 135.335
A38: 09/1976 | B38: 174.935
A39: 10/1976 | B39: 155.85
... A630: 01/2026 | B630: 2247

Sheet 出口印度
B1: 出口：印度
A2: 区域 | B2: 新加坡
A3: 次国家
A4: 频率 | B4: 月
A5: 单位 | B5: 百万新加坡元
A6: 数据来源 | B6: Enterprise Singapore
A7: 状态 | B7: 继续
A8: 数列ID | B8: 36423801 (SJFSA)
A9: SR码 | B9: SR520886
A10: 贸易代码
A11: 助记符
A12: 函数说明
A13: 首次观测日期 | B13: 01/1976
A14: 最后观测日期 | B14: 01/2026
A15: 最后更新时间 | B15: 16/02/2026
A16: 数列备注
A17: 建议
A18: 平均 MEAN | B18: 681.9086123128121
A19: 方差 | B19: 383583.89292648726
A20: 标准差 | B20: 619.3414994383045
A21: 偏度 | B21: 0.5792103500344982
A22: 峰度 | B22: -0.97722336
A23: 变异系数 | B23: 0.9082470704361684
A24: 最小 | B24: 6.407
A25: 最大 | B25: 2860.2
A26: 中位数 | B26: 400.357
A27: 总和 SUM | B27: 409827.0760000002
A28: 减 SUBTRACT | B28: -2853.793
A29: 参照期间 | B29: 601
A30: 01/1976 | B30: 9.368
A31: 02/1976 | B31: 9.328
A32: 03/1976 | B32: 10.472
A33: 04/1976 | B33: 6.431
A34: 05/1976 | B34: 8.892
A35: 06/1976 | B35: 8.74
A36: 07/1976 | B36: 10.637
A37: 08/1976 | B37: 11.026
A38: 09/1976 | B38: 10.11
A39: 10/1976 | B39: 10.112
... A630: 01/2026 | B630: 2162.6

Sheet 出口中国
B1: 出口：中国
A2: 区域 | B2: 新加坡
A3: 次国家
A4: 频率 | B4: 月
A5: 单位 | B5: 百万新加坡元
A6: 数据来源 | B6: Enterprise Singapore
A7: 状态 | B7: 继续
A8: 数列ID | B8: 36422101 (SJFD)
A9: SR码 | B9: SR520884
A10: 贸易代码
A11: 助记符
A12: 函数说明
A13: 首次观测日期 | B13: 01/1976
A14: 最后观测日期 | B14: 01/2026
A15: 最后更新时间 | B15: 16/02/2026
A16: 数列备注 | B16: [COVID-19-IMPACT]
A17: 建议
A18: 平均 MEAN | B18: 2464.1074392678847
A19: 方差 | B19: 7340876.363476348
A20: 标准差 | B20: 2709.4051678322953
A21: 偏度 | B21: 0.70484371
A22: 峰度 | B22: -0.96811967
A23: 变异系数 | B23: 1.0995483089151712
A24: 最小 | B24: 1.318
A25: 最大 | B25: 9215.9
A26: 中位数 | B26: 796.758
A27: 总和 SUM | B27: 1480928.5710000002
A28: 减 SUBTRACT | B28: -9214.582
A29: 参照期间 | B29: 601
A30: 01/1976 | B30: 11.604
A31: 02/1976 | B31: 8.486
A32: 03/1976 | B32: 1.318
A33: 04/1976 | B33: 2.867
A34: 05/1976 | B34: 2.018
A35: 06/1976 | B35: 7.193
A36: 07/1976 | B36: 3.263
A37: 08/1976 | B37: 6.876
A38: 09/1976 | B38: 3.677
A39: 10/1976 | B39: 3.934
... A630: 01/2026 | B630: 7443.3
